Workbook

Sheet 使用指南
A1: 使用指南
A2: 表單Owner | B2: Sophia
B3: 中文 | C3: Sophia
B4: 英文 | C4: Sophia
B5: 日文 | C5: 屈屈
B6: 韓文 | C6: Nana
B7: 此表單只會有多語言需要用的名詞，世界觀包裝請見另外的表單，請見目錄
A9: 目錄 | D9: 簡易查詢>> | E9: Endless Tides | F9: <<填寫這一格
A10: 項目 | B10: 分頁連結 | C10: 世界觀對應 (只有中文) | D10: 公式會自動跑 請勿調整 | E10: 英文 | F10: 日文 | G10: 韓文 | H10: 簡體中文
A11: 世界觀 | B11: https://docs.google.com/spreadsheets/d/1D_yJ9IFR-iYCGWxV30ELUYNCgEU8ZjHO_nV0QsXjonI/edit?gid=0#gid=0&range=A1 | D11: =$E$9 -> Endless Tides | E11: =ifna(vlookup(D11,'世界觀'!B:F,2,false),"") | F11: =ifna(vlookup(D11,'世界觀'!B:F,3,false),"") | G11: =ifna(vlookup(D11,'世界觀'!B:F,4,false),"") | H11: =ifna(vlookup(D11,'世界觀'!B:F,5,false),"")
A12: 光球 | B12: https://docs.google.com/spreadsheets/d/1D_yJ9IFR-iYCGWxV30ELUYNCgEU8ZjHO_nV0QsXjonI/edit?gid=1653246147#gid=1653246147&range=A1 | C12: https://docs.google.com/spreadsheets/d/1t8TKNmla7lHtQRDbSLiRXqfKHin_8imVbKuITRm1Rzw/edit?gid=343658773#gid=343658773&range=A1 | D12: =$E$9 -> Endless Tides | E12: =ifna(vlookup(D12,'光球'!B:F,2,false),"") | F12: =ifna(vlookup(D12,'光球'!B:F,3,false),"") | G12: =ifna(vlookup(D12,'光球'!B:F,4,false),"") | H12: =ifna(vlookup(D12,'光球'!B:F,5,false),"")
A13: 玩法與系統 | B13: https://docs.google.com/spreadsheets/d/1D_yJ9IFR-iYCGWxV30ELUYNCgEU8ZjHO_nV0QsXjonI/edit?gid=1154253793#gid=1154253793&range=A1 | C13: https://docs.google.com/spreadsheets/d/1t8TKNmla7lHtQRDbSLiRXqfKHin_8imVbKuITRm1Rzw/edit?gid=475591082#gid=475591082&range=A1 | D13: =$E$9 -> Endless Tides | E13: =ifna(vlookup(D13,'玩法與系統'!B:F,2,false),"") | F13: =ifna(vlookup(D13,'玩法與系統'!B:F,3,false),"") | G13: =ifna(vlookup(D13,'玩法與系統'!B:F,4,false),"") | H13: =ifna(vlookup(D13,'玩法與系統'!B:F,5,false),"")
A14: 技能 | B14: https://docs.google.com/spreadsheets/d/1D_yJ9IFR-iYCGWxV30ELUYNCgEU8ZjHO_nV0QsXjonI/edit?gid=500803902#gid=500803902&range=A1 | C14: https://docs.google.com/spreadsheets/d/1t8TKNmla7lHtQRDbSLiRXqfKHin_8imVbKuITRm1Rzw/edit?gid=1556590890#gid=1556590890&range=A1 | D14: =$E$9 -> Endless Tides | E14: =ifna(vlookup(D14,'技能'!B:F,2,false),"") | F14: =ifna(vlookup(D14,'技能'!B:F,3,false),"") | G14: =ifna(vlookup(D14,'技能'!B:F,4,false),"") | H14: =ifna(vlookup(D14,'技能'!B:F,5,false),"")
A15: 裝備 | B15: https://docs.google.com/spreadsheets/d/1D_yJ9IFR-iYCGWxV30ELUYNCgEU8ZjHO_nV0QsXjonI/edit?gid=1117083329#gid=1117083329&range=A1 | C15: https://docs.google.com/spreadsheets/d/1t8TKNmla7lHtQRDbSLiRXqfKHin_8imVbKuITRm1Rzw/edit?gid=1022532302#gid=1022532302&range=A1 | D15: =$E$9 -> Endless Tides | E15: =ifna(vlookup(D15,'裝備'!B:F,2,false),"") | F15: =ifna(vlookup(D15,'裝備'!B:F,3,false),"") | G15: =ifna(vlookup(D15,'裝備'!B:F,4,false),"") | H15: =ifna(vlookup(D15,'裝備'!B:F,5,false),"")
A16: 旅伴 | B16: https://docs.google.com/spreadsheets/d/1D_yJ9IFR-iYCGWxV30ELUYNCgEU8ZjHO_nV0QsXjonI/edit?gid=1117083329#gid=1117083329&range=A1 | C16: https://docs.google.com/spreadsheets/d/1t8TKNmla7lHtQRDbSLiRXqfKHin_8imVbKuITRm1Rzw/edit?gid=0#gid=0&range=A1 | D16: =$E$9 -> Endless Tides | E16: =ifna(vlookup(D16,'旅伴'!B:F,2,false),"") | F16: =ifna(vlookup(D16,'旅伴'!B:F,3,false),"") | G16: =ifna(vlookup(D16,'旅伴'!B:F,4,false),"") | H16: =ifna(vlookup(D16,'旅伴'!B:F,5,false),"")
A17: 道具 | B17: https://docs.google.com/spreadsheets/d/1D_yJ9IFR-iYCGWxV30ELUYNCgEU8ZjHO_nV0QsXjonI/edit?gid=1449090086#gid=1449090086&range=A1 | C17: https://docs.google.com/spreadsheets/d/1t8TKNmla7lHtQRDbSLiRXqfKHin_8imVbKuITRm1Rzw/edit?gid=168444671#gid=168444671&range=A1 | D17: =$E$9 -> Endless Tides | E17: =ifna(vlookup(D17,'道具'!B:F,2,false),"") | F17: =ifna(vlookup(D17,'道具'!B:F,3,false),"") | G17: =ifna(vlookup(D17,'道具'!B:F,4,false),"") | H17: =ifna(vlookup(D17,'道具'!B:F,5,false),"")
A18: 念痕 | B18: https://docs.google.com/spreadsheets/d/1D_yJ9IFR-iYCGWxV30ELUYNCgEU8ZjHO_nV0QsXjonI/edit?gid=936720670#gid=936720670&range=A1 | C18: https://docs.google.com/spreadsheets/d/1t8TKNmla7lHtQRDbSLiRXqfKHin_8imVbKuITRm1Rzw/edit?gid=1892301246#gid=1892301246&range=A1 | D18: =$E$9 -> Endless Tides | E18: =ifna(vlookup(D18,'念痕'!B:F,2,false),"") | F18: =ifna(vlookup(D18,'念痕'!B:F,3,false),"") | G18: =ifna(vlookup(D18,'念痕'!B:F,4,false),"") | H18: =ifna(vlookup(D18,'念痕'!B:F,5,false),"")
A19: 裝扮 | B19: https://docs.google.com/spreadsheets/d/1D_yJ9IFR-iYCGWxV30ELUYNCgEU8ZjHO_nV0QsXjonI/edit?gid=2057747304#gid=2057747304&range=A1 | D19: =$E$9 -> Endless Tides | E19: =ifna(vlookup(D19,'光球'!B:F,2,false),"") | F19: =ifna(vlookup(D19,'光球'!B:F,3,false),"") | G19: =ifna(vlookup(D19,'光球'!B:F,4,false),"") | H19: =ifna(vlookup(D19,'光球'!B:F,5,false),"") | I19: 尚未連動
D20: =$E$9 -> Endless Tides | E20: =ifna(vlookup(D20,'光球'!B:F,2,false),"") | F20: =ifna(vlookup(D20,'光球'!B:F,3,false),"") | G20: =ifna(vlookup(D20,'光球'!B:F,4,false),"") | H20: =ifna(vlookup(D20,'光球'!B:F,5,false),"") | I20: 尚未連動
D21: =$E$9 -> Endless Tides | E21: =ifna(vlookup(D21,'光球'!B:F,2,false),"") | F21: =ifna(vlookup(D21,'光球'!B:F,3,false),"") | G21: =ifna(vlookup(D21,'光球'!B:F,4,false),"") | H21: =ifna(vlookup(D21,'光球'!B:F,5,false),"") | I21: 尚未連動
D22: =$E$9 -> Endless Tides | E22: =ifna(vlookup(D22,'光球'!B:F,2,false),"") | F22: =ifna(vlookup(D22,'光球'!B:F,3,false),"") | G22: =ifna(vlookup(D22,'光球'!B:F,4,false),"") | H22: =ifna(vlookup(D22,'光球'!B:F,5,false),"") | I22: 尚未連動
A25: Memo欄用意 | B25: owner使用，其他人請忽略
A26: M | B26: master
A27: D | B27: dupilcate

Sheet 世界觀
A1: 世界觀
B2: ChineseTraditional | C2: English | D2: Japanese | E2: Korean | F2: ChineseSimplified
A3: Memo | B3: 中文 | C3: 英文 | D3: 日文 | E3: 韓文 | F3: 簡體中文
B4: 心源地 | C4: Emovia | D4: 心源地 | E4: 마음의 근원 | F4: 心源地
B5: 兇壓獸 | C5: Stress Monster | D5: 凶圧獣 | E5: 스트레스 몬스터 | F5: 凶压兽
B6: 兇壓巨獸 | C6: Stress Behemoth | D6: 凶圧巨獣 | E6: 스트레스 보스 | F6: 凶压巨兽
B7: EMO 情緒大爆炸！ | C7: EMO Blast! | D7: エモ•ブラスト！ | E7: EMO 서바이벌! | F7: EMO 情绪大爆炸！
B8: 旅伴 | C8: Companion | D8: 仲間 | E8: 동료 | F8: 旅伴

Sheet 光球
A1: 光球
B2: ChineseTraditional | C2: English | D2: Japanese | E2: Korean | F2: ChineseSimplified | G2: German | H2: French
A3: Memo | B3: 中文 | C3: 英文 | D3: 日文 | E3: 韓文 | F3: 簡體中文 | G3: 德文 | H3: 法文
B4: 光球 | C4: Lightling | D4: ヒカリル | E4: 빛의 정령 | F4: 光球
B5: 光光 | C5: Lumo | D5: ピカピカ | E5: 루모 | F5: 光光 | G5: Lumo | H5: Lumo
B6: 滾滾 | C6: Forma | D6: ゴロゴロ | E6: 포르마 | F6: 滚滚 | G6: Forma | H6: Forma
B7: 呼呼 | C7: Onus | D7: フーフー | E7: 오누스 | F7: 呼呼 | G7: Onus | H7: Onus
B8: 裝扮 | C8: Outfit | D8: 着替え | E8: 의상 | F8: 装扮

Sheet 裝扮
A1: 裝扮
B2: ChineseTraditional | C2: English | D2: Japanese | E2: Korean | F2: ChineseSimplified | G2: German | H2: French
A3: Memo | B3: 中文 | C3: 英文 | D3: 日文 | E3: 韓文 | F3: 簡體中文 | G3: 韓文 | H3: 法文
B4: 光光熾熱決心帽 | C4: Lumo’s Sparkfire Hat | D4: ピカピカの熱意ハット | E4: 루모 결심의 모자 | F4: 光光炽热决心帽
B5: 光光熱心胸章 | C5: Lumo’s Warmhearted Badge | D5: ピカピカの熱心バッジ | E5: 루모 열정 배지 | F5: 光光热心胸章
B6: 光光熱血炎翼 | C6: Lumo’s Emberwings | D6: ピカピカの熱血ウィング | E6: 루모 열혈 화염 날개 | F6: 光光热血炎翼
B7: 滾滾磐石盔 | C7: Forma’s Boulder Helm | D7: ゴロゴロの磐石カブト | E7: 포르마 바위 헬멧 | F7: 滚滚磐石盔
B8: 滾滾硬土徽章 | C8: Forma’s Earth Badge | D8: ゴロゴロの堅土バッジ | E8: 포르마 흙 배지 | F8: 滚滚硬土徽章
B9: 滾滾岩甲背盾 | C9: Forma’s Stoneplate Shield | D9: ゴロゴロの岩甲シールド | E9: 포르마 암석 등판 | F9: 滚滚岩甲背盾
B10: 呼呼茸帽 | C10: Onus’s Sprouting Cap | D10: フーフーの若芽ハット | E10: 오누스 버섯 모자 | F10: 呼呼茸帽
B11: 呼呼花露胸章 | C11: Onus’s Floral Badge | D11: フーフーの花雫バッジ | E11: 오누스 꽃이슬 배지 | F11: 呼呼花露胸章
B12: 呼呼蕨尾 | C12: Onus's Fern Tail | D12: フーフーの深緑テール | E12: 오누스 고사리 꼬리 | F12: 呼呼蕨尾
B13: 光光探險帽 | C13: Lumo’s Explorer Hat | D13: ピカピカの探検ハット | E13: 루모 탐험 모자 | F13: 光光探险帽
B14: 光光探野領巾 | C14: Lumo’s Wilderness Scarf | D14: ピカピカの荒野ヒレ | E14: 루모 야외 스카프 | F14: 光光探野领巾
B15: 光光野裝旅包 | C15: Lumo’s Venture Pack | D15: ピカピカの野装バッグ | E15: 루모 여행 가방 | F15: 光光野装旅包
... B27: 呼呼照顧者套裝 | C27: Onus Caregiver Set | D27: フーフーの守護者セット | E27: 오누스 서포터 세트 | F27: 呼呼照顾者套装

Sheet 玩法與系統
A1: 玩法與系統
B2: ChineseTraditional | C2: English | D2: Japanese | E2: Korean | F2: ChineseSimplified
A3: Memo | B3: 中文 | C3: 英文 | D3: 日文 | E3: 韓文 | F3: 簡體中文
B4: 心源探索 | C4: Emovia Voyage | D4: 心路の探索 | E4: 내면 탐색 | F4: 心源探索
B5: 心源深旅 | C5: Emovia Dive | D5: 心路の旅路 | E5: 마음 여정 | F5: 心源深旅
B6: 晝夜輪迴 | C6: Eternal Cycle | D6: 昼夜の輪廻 | E6: 무한 순환 | F6: 昼夜轮回
B7: 信念守護 | C7: Defense of Faith | D7: 信念の護り | E7: 신념 수호 | F7: 信念守护
B8: 金幣秘窟 | C8: Coin Cave | D8: 金貨の秘窟 | E8: 금화 동굴 | F8: 金币秘窟
B9: 歧路之擇 | C9: Road Not Taken | D9: 彷徨の岐路 | E9: 망설임의 길 | F9: 歧路之择
B10: 隨心換域 | C10: Drifting Realm | D10: 漂泊の領域 | E10: 자유 전환 | F10: 随心换域
B11: 無盡心潮 | C11: Endless Tides | D11: 無限の心潮 | E11: 감정 파도 | F11: 无尽心潮
B12: 心魔試煉 | C12: Final Nightmare | D12: 心魔の試練 | E12: 악의 시련 | F12: 心魔试炼
B13: 成長 | C13: Growth | D13: 成長 | E13: 성장 | F13: 成长
A14: M | B14: 旅伴 | C14: Companion | D14: 仲間 | E14: 동료 | F14: 旅伴
B15: 裝備 | C15: Gear | D15: 装備 | E15: 장비 | F15: 装备
B16: 念痕 | C16: Imprint | D16: 念痕 | E16: 각인 | F16: 念痕
B17: 收藏品 | C17: Collectibles | D17: コレクション | E17: 컬렉션 | F17: 收藏品
B18: 回憶片段 | C18: Memory Fragment | D18: 記憶の欠片
B19: 賽季通行證 | C19: Season Pass | D19: シーズンパス
B20: 商店 | C20: Shop | D20: ショップ
B21: 首儲獎勵 | C21: First Purchase Reward | D21: 初回購入ボーナス
B22: 月卡 | C22: Monthly Pass | D22: マンスリーパス
B23: 每日商店 | C23: Daily Shop | D23: デイリーショップ
B24: 每日特惠 | C24: Daily Specials | D24: 毎日お得パック
B25: 成長基金 | C25: Growth Fund | D25: 成長基金
B26: 晶龜 | C26: Soul Stone Tortoise | D26: 晶亀
B27: 旅伴助戰 | C27: Companion Deployment | D27: 仲間サポート

Sheet 技能
B2: ChineseTraditional | C2: English | D2: Japanese | E2: Korean | F2: ChineseSimplified
A3: Memo | B3: 中文 | C3: 英文 | D3: 日文 | E3: 韓文 | F3: 簡體中文
A4: M | B4: 尋音之琴 | C4: Seeker's Lyre | D4: 尋音のライアー | E4: 리듬의 리라 | F4: 寻音之琴
B5: 蒼穹尋律 | C5: Eternal Melody | D5: 悠遠の旋律 | E5: 창공의 리듬 | F5: 苍穹寻律
A6: M | B6: 吐槽折扇 | C6: Ridicule Fan | D6: 嘲笑のハリセン | E6: 독설 부채 | F6: 吐槽折扇
B7: 終極吐槽王 | C7: Roast Master | D7: 酷評の支配者 | E7: 독설왕 | F7: 终极吐槽王
A8: M | B8: 驚喜拉炮 | C8: Surprise Popper | D8: サプラィズ連砲 | E8: 깜짝 폭죽 | F8: 惊喜拉炮
B9: 驚喜連環爆 | C9: Party Time | D9: 狂乱の祝祭 | E9: 연속 깜짝 폭발 | F9: 惊喜连环爆
A10: M | B10: 貪欲權杖 | C10: Greed Scepter | D10: 強欲の権化 | E10: 탐욕의 지팡이 | F10: 贪欲权杖
B11: 貪狼星審判日 | C11: Wolfstar Judgement | D11: 貪狼の断罪日 | E11: 탐랑성의 심판일 | F11: 贪狼星审判日
A12: M | B12: 傲慢玫瑰 | C12: Rose of Pride | D12: 誇りの薔薇 | E12: 오만한 장미 | F12: 傲慢玫瑰
B13: 傲嬌之華 | C13: Pride and Prejudice | D13: 矜持の徒花 | E13: 오만의 개화 | F13: 傲娇之华
A14: M | B14: 戒備之鈴 | C14: Warningbell | D14: 戒備の鈴 | E14: 경계의 종 | F14: 戒备之铃
B15: 浩劫警鐘 | C15: Doom Ring | D15: 厄災の風鈴 | E15: 파멸의 종 | F15: 浩劫警钟
A16: M | B16: 夢想破滅 | C16: Shattered Dream | D16: 夢幻の泡 | E16: 무너진 꿈 | F16: 梦想破灭
B17: 絢爛空殼 | C17: Hollow Brilliance | D17: 絢爛の虚殻 | E17: 공허한 광채 | F17: 绚烂空壳
B18: 忌妒之箭 | C18: Arrow of Envy | D18: 嫉妬の弓矢 | E18: 질투의 화살 | F18: 忌妒之箭
B19: 醋意穿心 | C19: Envy Piercer | D19: 悋気の貫撃 | E19: 질투의 명중 | F19: 醋意穿心
B20: 哭泣冰球 | C20: Cold Tears | D20: 悲嘆の氷涙 | E20: 차가운 눈물 | F20: 哭泣冰球
B21: 永夜寒淚 | C21: Nightfall Tears | D21: 永夜の晶涙 | E21: 한기의 눈물 | F21: 永夜寒泪
B22: 希望之星 | C22: Star of Hope | D22: 希望の輝星 | E22: 희망의 별 | F22: 希望之星
B23: 光之約定 | C23: Light Oath | D23: 至光の盟約 | E23: 빛의 약속 | F23: 光之约定
B24: 畏懼之鳥 | C24: Dreadwing | D24: 恐畏の紋翼 | E24: 불안의 새 | F24: 畏惧之鸟
B25: 夢魘圖紋 | C25: Nightmare Sigil | D25: 悪夢の刻印 | E25: 악몽의 문양 | F25: 梦魇图纹
B26: 憤怒隕石 | C26: Ragefall Meteor | D26: 憤怒の隕石 | E26: 분노의 운석 | F26: 愤怒陨石
B27: 末日狂怒 | C27: Doomsday Fury | D27: 終焉の憤怒 | E27: 종말의 격노 | F27: 末日狂怒
B28: 困惑之風 | C28: Gust of Confusion | D28: 困惑の渦風 | E28: 혼란의 바람 | F28: 困惑之风
... B63: 小包袱 | C63: Sweet Burden | D63: プニョ三連星 | E63: 작은 꾸러미 | F63: 小包袱

Sheet 裝備
A1: 裝備
B2: ChineseTraditional | C2: English | D2: Japanese | E2: Korean | F2: ChineseSimplified
A3: Memo | B3: 中文 | C3: 英文 | D3: 日文 | E3: 韓文 | F3: 簡體中文
A4: D | B4: 尋音之琴 | C4: ='技能'!C4 -> Seeker's Lyre | D4: ='技能'!D4 -> 尋音のライアー | E4: ='技能'!E4 -> 리듬의 리라 | F4: ='技能'!F4 -> 寻音之琴
A5: D | B5: 吐槽折扇 | C5: ='技能'!C6 -> Ridicule Fan | D5: ='技能'!D6 -> 嘲笑のハリセン | E5: ='技能'!E6 -> 독설 부채 | F5: ='技能'!F6 -> 吐槽折扇
A6: D | B6: 驚喜拉炮 | C6: ='技能'!C8 -> Surprise Popper | D6: ='技能'!D8 -> サプラィズ連砲 | E6: ='技能'!E8 -> 깜짝 폭죽 | F6: ='技能'!F8 -> 惊喜拉炮
A7: D | B7: 貪欲權杖 | C7: ='技能'!C10 -> Greed Scepter | D7: ='技能'!D10 -> 強欲の権化 | E7: ='技能'!E10 -> 탐욕의 지팡이 | F7: ='技能'!F10 -> 贪欲权杖
A8: D | B8: 傲慢玫瑰 | C8: ='技能'!C12 -> Rose of Pride | D8: ='技能'!D12 -> 誇りの薔薇 | E8: ='技能'!E12 -> 오만한 장미 | F8: ='技能'!F12 -> 傲慢玫瑰
A9: D | B9: 戒備之鈴 | C9: ='技能'!C14 -> Warningbell | D9: ='技能'!D14 -> 戒備の鈴 | E9: ='技能'!E14 -> 경계의 종 | F9: ='技能'!F14 -> 戒备之铃
A10: D | B10: 夢想破滅 | C10: ='技能'!C16 -> Shattered Dream | D10: ='技能'!D16 -> 夢幻の泡 | E10: 무너진 꿈 | F10: ='技能'!F16 -> 梦想破灭
B11: 夢想天地 | C11: Dream Realm | D11: 夢の天地 | E11: 꿈의 텐트 | F11: 梦想天地
B12: 夢想行囊 | C12: Dream Bag | D12: 夢のバッグ | E12: 꿈의 가방 | F12: 梦想行囊
B13: 夢想披風 | C13: Dream Cape | D13: 夢のケープ | E13: 꿈의 망토 | F13: 梦想披风
B14: 夢想許願燈 | C14: Dream Lantern | D14: 夢の願い灯 | E14: 꿈의 소원등 | F14: 梦想许愿灯
B15: 夢想手套 | C15: Dream Gloves | D15: 夢のグローブ | E15: 꿈의 장갑 | F15: 梦想手套
B16: 征服者營帳 | C16: Conqueror Tent | D16: 征服者の野営帳 | E16: 정복자의 천막 | F16: 征服者营帐
B17: 征服者行囊 | C17: Conqueror Pack | D17: 征服者のバッグ | E17: 정복자의 가방 | F17: 征服者行囊
B18: 征服者披風 | C18: Conqueror Cape | D18: 征服者のケープ | E18: 정복자의 망토 | F18: 征服者披风
B19: 征服者火盞 | C19: Conqueror Torch | D19: 征服者のトーチ | E19: 정복자의 등불 | F19: 征服者火盏
B20: 征服者手套 | C20: Conqueror Gloves | D20: 征服者のグローブ | E20: 정복자의 장갑 | F20: 征服者手套
B21: 偽裝葉棚 | C21: Leafshade Shelter | D21: 身隠しのシェルター | E21: 위장 잎 천막 | F21: 伪装叶棚
B22: 野林採集囊 | C22: Forager Pouch | D22: 採集者の袋 | E22: 야생 채집 가방 | F22: 野林采集囊
... B52: 合成 | C52: craft | D52: クラフト | E52: 합성 | F52: 合成
B53: 光鑄 | C53: Lightcast | D53: 光鋳 | E53: 재련
B54: 神器 | D54: レリック | E54: 유물

Sheet 旅伴
A1: 旅伴
B2: ChineseTraditional | C2: English | D2: Japanese | E2: Korean | F2: ChineseSimplified
A3: Memo | B3: 中文 | C3: 英文 | D3: 日文 | E3: 韓文 | F3: 簡體中文
B4: 驚嚇蛙 | C4: Jumpie | D4: オドロクン | E4: 깜짝개굴 | F4: 惊吓蛙
B5: 蛙蛙叫 | C5: Croak Shock | D5: ゲロ鳴く | E5: 개굴개굴 | F5: 蛙蛙叫
B6: 蛙鳴驚人 | C6: Ribbit Riot | D6: ゲロ驚く | E6: 개굴파워 | F6: 蛙鸣惊人
B7: 暴怒猴 | C7: Grumpie | D7: バクサル | E7: 깨부숭 | F7: 暴怒猴
B8: 怒氣砰砰 | C8: Boomrage | D8: バンバン怒り | E8: 분노충전 | F8: 怒气砰砰
B9: 猴力全開 | C9: Monkey Power | D9: モンキー１００％ | E9: 분노파워 | F9: 猴力全开
B10: 溫柔兔 | C10: Milddie | D10: ヤサギ | E10: 젠틀빗 | F10: 温柔兔
B11: 軟綿綿攻擊 | C11: Pillow Pounce | D11: ふわふわパンチ | E11: 푹신푹신 펀치 | F11: 软绵绵攻击
B12: 溫柔引力 | C12: Gentle Pull | D12: 柔かい引力 | E12: 신사의 품격 | F12: 温柔引力
B13: 快樂鼠 | C13: Cheerie | D13: ハピネチュウ | E13: 해피쥐 | F13: 快乐鼠
B14: 糖果子彈 | C14: Candy Shot | D14: 飴ショット | E14: 캔디 불렛 | F14: 糖果子弹
B15: 甜甜圈圈 | C15: Time for Sweets | D15: ドーナリング | E15: 메리엔다 | F15: 甜甜圈圈
... B27: 正義撞擊 | C27: Justice Charge | D27: セイギダッシュ | E27: 정의의 돌진 | F27: 正义撞击
A28: D | B28: 旅伴 | C28: ='玩法與系統'!C14 -> Companion | D28: ='玩法與系統'!D14 -> 仲間 | E28: ='玩法與系統'!E14 -> 동료 | F28: 旅伴
B29: 敏感旅伴 | C29: Sensitive Companion | D29: 敏感タイプ | E29: 감정 반응형 | F29: 敏感旅伴
B30: 暖心旅伴 | C30: Warm Companion | D30: 治癒タイプ | E30: 온기 지원형 | F30: 暖心旅伴
B31: 激進旅伴 | C31: Progressive Companion | D31: 猛攻タイプ | E31: 정신 피해형 | F31: 激进旅伴
B32: 靜默旅伴 | C32: Reflective Companion | D32: 静寂タイプ | E32: 성찰 반격형 | F32: 静默旅伴
B33: 好感度 | C33: Affection

Sheet 道具
B2: ChineseTraditional | C2: English | D2: Japanese | E2: Korean | F2: ChineseSimplified | G2: German | H2: French
A3: Memo | B3: 中文 | C3: 英文 | D3: 日文 | E3: 韓文 | F3: 簡體中文 | G3: 德文 | H3: 法文
B4: 三角飯糰 | C4: Rice Ball | D4: おにぎり | E4: 삼각 김밥 | F4: =IFERROR(__xludf.DUMMYFUNCTION("GOOGLETRANSLATE(B4,""zh-TW"",""zh-CN"")"),"三角饭团") -> 三角饭团
B5: 三明治 | C5: Sandwich | D5: サンドイッチ | E5: 샌드위치 | F5: =IFERROR(__xludf.DUMMYFUNCTION("GOOGLETRANSLATE(B5,""zh-TW"",""zh-CN"")"),"三明治") -> 三明治
B6: 心力 | C6: Stamina | D6: 心力 | E6: 스태미나 | F6: =IFERROR(__xludf.DUMMYFUNCTION("GOOGLETRANSLATE(B6,""zh-TW"",""zh-CN"")"),"心力") -> 心力
B7: 金幣 (大) | C7: Coin (L) | D7: 金貨 (大) | E7: 금화(대) | F7: =IFERROR(__xludf.DUMMYFUNCTION("GOOGLETRANSLATE(B7,""zh-TW"",""zh-CN"")"),"金币 (大)") -> 金币 (大)
B8: 金幣 (小) | C8: Coin (S) | D8: 金貨 (小) | E8: 금화(중) | F8: =IFERROR(__xludf.DUMMYFUNCTION("GOOGLETRANSLATE(B8,""zh-TW"",""zh-CN"")"),"金币 (小)") -> 金币 (小)
B9: 金幣 (中) | C9: Coin (M) | D9: 金貨 (中) | E9: 금화(소) | F9: =IFERROR(__xludf.DUMMYFUNCTION("GOOGLETRANSLATE(B9,""zh-TW"",""zh-CN"")"),"金币 (中)") -> 金币 (中)
B10: 心塵秘窟掃蕩券 | C10: Coin Cave Sweep Ticket | D10: 金貨秘窟スキップ券 | E10: 금화 동굴 소탕권 | F10: =IFERROR(__xludf.DUMMYFUNCTION("GOOGLETRANSLATE(B10,""zh-TW"",""zh-CN"")"),"心尘秘窟扫荡券") -> 心尘秘窟扫荡券
B11: 心魔試煉入場券 | C11: Final Nightmare Ticket | D11: 心魔の試練入場券 | E11: 악의 시련 입장권 | F11: =IFERROR(__xludf.DUMMYFUNCTION("GOOGLETRANSLATE(B11,""zh-TW"",""zh-CN"")"),"心魔试炼入场券") -> 心魔试炼入场券
B12: 手套圖紙 | C12: Gloves Blueprint | D12: グローブ設計図 | E12: 장갑 도면 | F12: =IFERROR(__xludf.DUMMYFUNCTION("GOOGLETRANSLATE(B12,""zh-TW"",""zh-CN"")"),"手套图纸") -> 手套图纸
B13: 火焰之花 | C13: Blazing Bloom | D13: 炎の花 | E13: 불의 꽃 | F13: =IFERROR(__xludf.DUMMYFUNCTION("GOOGLETRANSLATE(B13,""zh-TW"",""zh-CN"")"),"火焰之花") -> 火焰之花
B14: 可頌麵包 | C14: Croissant | D14: クロワッサン | E14: 크루아상 | F14: =IFERROR(__xludf.DUMMYFUNCTION("GOOGLETRANSLATE(B14,""zh-TW"",""zh-CN"")"),"可颂面包") -> 可颂面包
B15: 史詩手套通用材料 | C15: General Gloves Crafting Material (Epic) | D15: 英雄のグローブ汎用材料 | E15: 에픽 장갑 공용 재료 | F15: =IFERROR(__xludf.DUMMYFUNCTION("GOOGLETRANSLATE(B15,""zh-TW"",""zh-CN"")"),"史诗手套通用材料") -> 史诗手套通用材料
B16: 史詩行囊通用材料 | C16: General Satchel Crafting Material (Epic) | D16: 英雄のバッグ汎用材料 | E16: 에픽 가방 공용 재료 | F16: =IFERROR(__xludf.DUMMYFUNCTION("GOOGLETRANSLATE(B16,""zh-TW"",""zh-CN"")"),"史诗行囊通用材料") -> 史诗行囊通用材料
B17: 史詩披風通用材料 | C17: General Cloak Crafting Material (Epic) | D17: 英雄のケープ汎用材料 | E17: 에픽 망토 공용 재료 | F17: =IFERROR(__xludf.DUMMYFUNCTION("GOOGLETRANSLATE(B17,""zh-TW"",""zh-CN"")"),"史诗披风通用材料") -> 史诗披风通用材料
B18: 史詩武器通用材料 | C18: General Weapon Crafting Material (Epic) | D18: 英雄の武器汎用材料 | E18: 에픽 무기 공용 재료 | F18: =IFERROR(__xludf.DUMMYFUNCTION("GOOGLETRANSLATE(B18,""zh-TW"",""zh-CN"")"),"史诗武器通用材料") -> 史诗武器通用材料
B19: 史詩帳篷通用材料 | C19: General Tent Crafting Material (Epic) | D19: 英雄のテント汎用材料 | E19: 에픽 텐트 공용 재료 | F19: =IFERROR(__xludf.DUMMYFUNCTION("GOOGLETRANSLATE(B19,""zh-TW"",""zh-CN"")"),"史诗帐篷通用材料") -> 史诗帐篷通用材料
B20: 史詩燈具通用材料 | C20: General Lantern Crafting Material (Epic) | D20: 英雄のランプ汎用材料 | E20: 에픽 조명 공용 재료 | F20: =IFERROR(__xludf.DUMMYFUNCTION("GOOGLETRANSLATE(B20,""zh-TW"",""zh-CN"")"),"史诗灯具通用材料") -> 史诗灯具通用材料
B21: 奶油鬆餅 | C21: Cream Waffle | D21: クリームワッフル | E21: 생크림 팬케이크 | F21: =IFERROR(__xludf.DUMMYFUNCTION("GOOGLETRANSLATE(B21,""zh-TW"",""zh-CN"")"),"奶油松饼") -> 奶油松饼
B22: 巧克力夾心餅乾 | C22: Chocolate Cookie | D22: チョコサンド | E22: 초코 샌드 쿠키 | F22: =IFERROR(__xludf.DUMMYFUNCTION("GOOGLETRANSLATE(B22,""zh-TW"",""zh-CN"")"),"巧克力夹心饼干") -> 巧克力夹心饼干
B23: 永生水母 | C23: Immortal Jellyfish | D23: 不死身のクラゲ | E23: 영생 해파리 | F23: =IFERROR(__xludf.DUMMYFUNCTION("GOOGLETRANSLATE(B23,""zh-TW"",""zh-CN"")"),"永生水母") -> 永生水母
B24: 生菜沙拉 | C24: Lettuce Salad | D24: レタスサラダ | E24: 그린 샐러드 | F24: =IFERROR(__xludf.DUMMYFUNCTION("GOOGLETRANSLATE(B24,""zh-TW"",""zh-CN"")"),"生菜沙拉") -> 生菜沙拉
B25: 光之紙：征服 | C25: Light Script: Conquest | D25: 光の紙：征服 | E25: 빛의 종이: 정복 | F25: =IFERROR(__xludf.DUMMYFUNCTION("GOOGLETRANSLATE(B25,""zh-TW"",""zh-CN"")"),"光之纸：征服") -> 光之纸：征服
B26: 光之紙：夢想 | C26: Light Script: Dream | D26: 光の紙：夢想 | E26: 빛의 종이: 꿈 | F26: =IFERROR(__xludf.DUMMYFUNCTION("GOOGLETRANSLATE(B26,""zh-TW"",""zh-CN"")"),"光之纸：梦想") -> 光之纸：梦想
B27: 光光結晶 | C27: Lumo Crystal | D27: ヒカリルの結晶 | E27: 루모의 결정 | F27: =IFERROR(__xludf.DUMMYFUNCTION("GOOGLETRANSLATE(B27,""zh-TW"",""zh-CN"")"),"光光结晶") -> 光光结晶
B28: 光球重置藥水 | C28: Lightling Reset Elixir | D28: ヒカリルの還元液 | E28: 빛의 정령 초기화 물약 | F28: =IFERROR(__xludf.DUMMYFUNCTION("GOOGLETRANSLATE(B28,""zh-TW"",""zh-CN"")"),"光球重置药水") -> 光球重置药水
B29: 光球能量 | C29: Lightling Energy | D29: ヒカリルのエネルギー | E29: 빛의 정령 에너지 | F29: =IFERROR(__xludf.DUMMYFUNCTION("GOOGLETRANSLATE(B29,""zh-TW"",""zh-CN"")"),"光球能量") -> 光球能量
B30: 光鑄素材 | C30: Lightcast Material | D30: 光鋳の素材 | E30: 재련 재료 | F30: =IFERROR(__xludf.DUMMYFUNCTION("GOOGLETRANSLATE(B30,""zh-TW"",""zh-CN"")"),"光铸素材") -> 光铸素材
B31: 共鳴升級光芒 | C31: Resonance Upgrade Glow | D31: 共鳴強化の光 | E31: 공명 강화의 빛 | F31: =IFERROR(__xludf.DUMMYFUNCTION("GOOGLETRANSLATE(B31,""zh-TW"",""zh-CN"")"),"共鸣升级光芒") -> 共鸣升级光芒
B32: 冰淇淋 | C32: Ice Cream | D32: アイスクリーム | E32: 아이스크림 | F32: =IFERROR(__xludf.DUMMYFUNCTION("GOOGLETRANSLATE(B32,""zh-TW"",""zh-CN"")"),"冰淇淋") -> 冰淇淋
B33: 冰塊 | C33: Ice Cube | D33: アイスキューブ | E33: 얼음 | F33: =IFERROR(__xludf.DUMMYFUNCTION("GOOGLETRANSLATE(B33,""zh-TW"",""zh-CN"")"),"冰块") -> 冰块
B34: 守護徽章 | C34: Guardian Emblem | D34: 守護の紋章 | E34: 수호 배지 | F34: =IFERROR(__xludf.DUMMYFUNCTION("GOOGLETRANSLATE(B34,""zh-TW"",""zh-CN"")"),"守护徽章") -> 守护徽章
B35: 收藏品寶箱鑰匙 | C35: Collectibles Chest Key | D35: コレクション宝箱の鍵 | E35: 수집품 상자 열쇠 | F35: =IFERROR(__xludf.DUMMYFUNCTION("GOOGLETRANSLATE(B35,""zh-TW"",""zh-CN"")"),"收藏品宝箱钥匙") -> 收藏品宝箱钥匙
B36: 自選光球結晶 | C36: Selection Lightling Crystal Chest | D36: セレクトヒカリル結晶 | E36: 빛의 정령 결정 선택 | F36: =IFERROR(__xludf.DUMMYFUNCTION("GOOGLETRANSLATE(B36,""zh-TW"",""zh-CN"")"),"自选光球结晶") -> 自选光球结晶
A37: S | B37: 自選寶箱 - 回憶片段 第1期(精良) | C37: Choice Chest - Memory Fragment 1st Edition(Refined) | D37: 選べる宝箱 - 回想の断片 第1弾 (上質) | E37: 선택 상자- 기억 조각 시즌1 (고급) | F37: =IFERROR(__xludf.DUMMYFUNCTION("GOOGLETRANSLATE(B37,""zh-TW"",""zh-CN"")"),"自选宝箱 - 回忆片段 第1期(精良)") -> 自选宝箱 - 回忆片段 第1期(精良)
A38: S | B38: 自選寶箱 - 回憶片段 第1期(優秀) | C38: Choice Chest - Memory Fragment 1st Edition(Rare) | D38: 選べる宝箱 - 回想の断片 第1弾 (優秀) | E38: 선택 상자- 기억 조각 시즌1 (희귀) | F38: =IFERROR(__xludf.DUMMYFUNCTION("GOOGLETRANSLATE(B38,""zh-TW"",""zh-CN"")"),"自选宝箱 - 回忆片段 第1期(优秀)") -> 自选宝箱 - 回忆片段 第1期(优秀)
A39: S | B39: 自選寶箱 - 回憶片段 第1期(傑出) | C39: Choice Chest - Memory Fragment 1st Edition(Elite) | D39: 選べる宝箱 - 回想の断片 第1弾 (卓越) | E39: 선택 상자- 기억 조각 시즌1 (영웅) | F39: =IFERROR(__xludf.DUMMYFUNCTION("GOOGLETRANSLATE(B39,""zh-TW"",""zh-CN"")"),"自选宝箱 - 回忆片段 第1期(杰出)") -> 自选宝箱 - 回忆片段 第1期(杰出)
A40: S | B40: 自選寶箱 - 回憶片段 第1期(史詩) | C40: Choice Chest - Memory Fragment 1st Edition(Epic) | D40: 選べる宝箱 - 回想の断片 第1弾 (英雄) | E40: 선택 상자- 기억 조각 시즌1 (에픽) | F40: =IFERROR(__xludf.DUMMYFUNCTION("GOOGLETRANSLATE(B40,""zh-TW"",""zh-CN"")"),"自选宝箱 - 回忆片段 第1期(史诗)") -> 自选宝箱 - 回忆片段 第1期(史诗)
A41: S | B41: 自選寶箱 - 回憶片段 第1期(傳奇) | C41: Choice Chest - Memory Fragment 1st Edition(Legendary) | D41: 選べる宝箱 - 回想の断片 第1弾 (伝説) | E41: 선택 상자- 기억 조각 시즌1 (전설) | F41: =IFERROR(__xludf.DUMMYFUNCTION("GOOGLETRANSLATE(B41,""zh-TW"",""zh-CN"")"),"自选宝箱 - 回忆片段 第1期(传奇)") -> 自选宝箱 - 回忆片段 第1期(传奇)
...

Sheet 念痕
A1: 念痕
B2: ChineseTraditional | C2: English | D2: Japanese | E2: Korean | F2: ChineseSimplified
A3: Memo | B3: 中文 | C3: 英文 | D3: 日文 | E3: 韓文 | F3: 簡體中文
B4: 忌妒綠幽靈 | C4: Green Envy | D4: 嫉妬の緑霊 | E4: 질투의 유령 | F4: 忌妒绿幽灵
B5: 人魚之淚 | C5: Mermaid's Tear | D5: 人魚の涙 | E5: 인어의 눈물 | F5: 人鱼之泪
B6: 幸運之草 | C6: Lucky Clover | D6: 幸運のクローバー | E6: 행운의 클로버 | F6: 幸运之草
B7: 恐懼蜘蛛網 | C7: Web of Fear | D7: 恐怖の網 | E7: 공포의 거미줄 | F7: 恐惧蜘蛛网
B8: 憤怒之眼 | C8: Eye of Wrath | D8: 怒りの眼球 | E8: 분노의 눈 | F8: 愤怒之眼
B9: 迷宮球 | C9: Maze Orb | D9: 迷宮のオーブ | E9: 미궁 구슬 | F9: 迷宫球
B10: 歡樂糖果 | C10: Glee Gummy | D10: 歓喜のキャンディ | E10: 행복 젤리 | F10: 欢乐糖果
B11: 煩躁烏雲 | C11: Grumpy Cloud | D11: 苛立ちの暗雲 | E11: 짜증의 먹구름 | F11: 烦躁乌云
B12: 興奮彩虹 | C12: Thrillbow | D12: 興奮の虹 | E12: 흥분의 무지개 | F12: 兴奋彩虹
B13: 啟蒙之帽 | C13: Thinking Hat | D13: 啓蒙の帽子 | E13: 계몽의 모자 | F13: 启蒙之帽
B14: 歷史線索 | C14: Historical Clue | D14: 歴史の手がかり | E14: 역사 단서 | F14: 历史线索
B15: 幸福齒輪 | C15: Blissful Gear | D15: 幸福の歯車 | E15: 행복의 톱니바퀴 | F15: 幸福齿轮
... B18: 動力羅盤 | C18: Power Compass | D18: 昂揚のコンパス | E18: 동력 나침반 | F18: 动力罗盘

Sheet 其他
A1: 其他
B2: ChineseTraditional | C2: English | D2: Japanese | E2: Korean | F2: ChineseSimplified
A3: Memo | B3: 中文 | C3: 英文 | D3: 日文 | E3: 韓文 | F3: 簡體中文
A4: 灰 | B4: 普通 | C4: Common | D4: 普通 | E4: 일반 | F4: 普通
A5: 綠 | B5: 精良 | C5: Refined | D5: 上質 | E5: 고급 | F5: 精良
A6: 藍 | B6: 優秀 | C6: Rare | D6: 優秀 | E6: 희귀 | F6: 优秀
A7: 紫 | B7: 傑出 | C7: Elite | D7: 卓越 | E7: 영웅 | F7: 杰出
A8: 金 | B8: 史詩 | C8: Epic | D8: 英雄 | E8: 에픽 | F8: 史诗
A9: 紅 | B9: 傳奇 | C9: Legendary | D9: 伝説 | E9: 전설 | F9: 传奇
B10: 天 | C10: Day | D10: 日 | E10: 일 | F10: 天
B11: 材料 | C11: Material | D11: 材料 | E11: 재료 | F11: 材料
B12: 品質 | C12: quality | D12: 品質 | E12: 등급 | F12: 质量
B13: 防禦 | C13: Defense | D13: 防御 | E13: 방어 | F13: 防御
B14: 戰力值 | C14: Combat Power | D14: 戦力値 | E14: 공격력 | F14: 战力值
B15: 攻擊 | C15: Attack | D15: 攻撃 | E15: 공격 | F15: 攻击
B16: 生命 | C16: Health | D16: 生命 | E16: 생명력 | F16: 生命
B17: S級 | C17: S-grade | D17: S級 | E17: S급 | F17: S级

Sheet 敵人
A1: 敵人字典
B2: ChineseTraditional | C2: English | D2: Japanese | E2: Korean | F2: ChineseSimplified | G2: German | H2: French
A3: Memo | B3: 中文 | C3: 英文 | D3: 日文 | E3: 韓文 | F3: 簡體中文 | G3: 德文 | H3: 法文
B4: 面具鹿角獸 | C4: Masked Elk | D4: 仮面の角鹿 | E4: 사슴뿔 가면
B5: 執念束縛靈 | C5: Binding Banshee | D5: 執着の縛霊 | E5: 집작하는 유령
B6: 滑稽傀儡熊 | C6: Ludicrous Teddy | D6: 滑稽なドールベア | E6: 광대 곰
B7: 冠軍鬥拳王 | D7: 覇道の拳王 | E7: 챔피언 권투왕
B8: 時間審判官 | D8: 時の審判官 | E8: 시간 심판관
B9: 冷眼君王 | C9: Cold-Eyed King | D9: 冷徹なる君主 | E9: 냉혈한 군주
B10: 千面微笑球 | D10: 微笑む千面球 | E10: 천개의 얼굴
B11: 體制蜂巢主 | C11: Hive Master | D11: 統制の女王蜂 | E11: 군단 질서의 주인
B12: 監視狂球 | D12: 監視の狂球 | E12: 감시광 공
B13: 偽善黑影狼 | D13: 偽善の影狼 | E13: 위선의 흑랑
B14: 災厄之蛾 | D14: 災厄の蛾 | E14: 재앙의 나방
B15: 虛榮滿月 | D15: 虚栄の満月 | E15: 허영의 보름달
B16: 貪婪暴食魔 | D16: 飽くなき暴食魔 | E16: 탐식의 마왕
B17: 爛泥吞噬者 | D17: 泥濘の貪食者 | E17: 진흙 포식자
B18: 無盡貪婪獸 | D18: 無窮の強欲獣 | E18: 끝없는 탐욕수
B19: 眼淚勒索者 | D19: 涙の強請者 | E19: 눈물 수집가
B20: 空洞巨靈 | D20: 空虚の巨霊 | E20: 공허한 유령
B21: 完美無瑕之花 | D21: 完璧なる極花 | E21: 완전무결한 꽃
B22: 光芒貪食者 | D22: 光を奪う者 | E22: 빛의 탐식자
B23: 重擔巨鯨 | D23: 重荷の巨鯨 | E23: 무거운 대왕 고래
... B28: 知識牢籠 | D28: 叡智の檻 | E28: 지식의 감옥
B29: 思緒爆裂王 | C29: Mindshatter King | D29: 思念の爆裂王 | E29: 사고폭주의 왕
B30: 三疊心魔 | C30: Triple Demon | D30: 三重の心魔 | E30: 내면의 악마
B31: 糖霜腐蝕蟹 | D31: 糖衣の腐蝕蟹 | E31: 눈설탕 부식 게
B32: 金幣巨蝦蝦 | C32: Giant Coin Shrimp | D32: 金貨のエビ王 | E32: 금화 거대 새우

Sheet 頭像
A1: 頭像
B2: ChineseTraditional | C2: English | D2: Japanese | E2: Korean | F2: ChineseSimplified
A3: Memo | B3: 中文 | C3: 英文 | D3: 日文 | E3: 韓文 | F3: 簡體中文
B4: 初芽光光頭像 | C4: Lumo Sprout Avatar | D4: 若葉ピカピカアイコン | E4: 루모 새싹 프로필

Sheet 相框
A1: 相框
B2: ChineseTraditional | C2: English | D2: Japanese | E2: Korean | F2: ChineseSimplified
A3: Memo | B3: 中文 | C3: 英文 | D3: 日文 | E3: 韓文 | F3: 簡體中文
B4: 初芽光光相框 | C4: Lumo Sprout Frame | D4: 若葉ピカピカ若葉フレーム | E4: 루모 새싹 테두리
